2021-05-18 15:12:21,235	INFO worker.py:677 -- Connecting to existing Ray cluster at address: 10.138.0.51:6379
node:10.138.0.51 node:10.138.0.30
node:10.138.0.51
^CTraceback (most recent call last):
  File "/home/ubuntu/read_workload_simple.py", line 143, in <module>
    benchmark(o,w)
  File "/home/ubuntu/read_workload_simple.py", line 103, in benchmark
    [ref_list1] = ray.get(ref)
  File "/home/ubuntu/ray/python/ray/_private/client_mode_hook.py", line 47, in wrapper
    return func(*args, **kwargs)
  File "/home/ubuntu/ray/python/ray/worker.py", line 1443, in get
    object_refs, timeout=timeout)
  File "/home/ubuntu/ray/python/ray/worker.py", line 332, in get_objects
    object_refs, self.current_task_id, timeout_ms)
  File "python/ray/_raylet.pyx", line 936, in ray._raylet.CoreWorker.get_objects
  File "python/ray/_raylet.pyx", line 148, in ray._raylet.check_status
KeyboardInterrupt
^CError in atexit._run_exitfuncs:
Traceback (most recent call last):
  File "/home/ubuntu/ray/python/ray/_private/client_mode_hook.py", line 47, in wrapper
2021-05-18 15:12:29,453	DEBUG (unknown file):0 -- gc.collect() freed 4 refs in 0.030646136998257134 seconds
    return func(*args, **kwargs)
  File "/home/ubuntu/ray/python/ray/worker.py", line 838, in shutdown
    time.sleep(0.5)
KeyboardInterrupt
[0m^C
Loaded cached provider configuration
If you experience issues with the cloud provider, try re-running the command with --no-config-cache.
Fetched IP: 35.227.160.252
Fetched IP: 35.227.160.252
